Workbook

Sheet Input Data
A1: VelocityTech Inc. — Source Financial Data (US$ millions)
A2: Free Cash Flow & Earnings Quality — Forensic Analysis | Group 8 | Due: 31 March
A3: Item | B3: FY 2025 | C3: FY 2024 | D3: Notes
A4: Revenue | B4: 5200 | C4: 3900 | D4: Reported top-line revenue
A5: Net Income | B5: 780 | C5: 507 | D5: GAAP net income after tax
A6: Depreciation & Amortisation | B6: 260 | C6: 195 | D6: Non-cash add-back
A7: Stock-Based Compensation (non-cash) | B7: 390 | C7: 234 | D7: Non-cash; real economic cost
A8: Increase in Accounts Receivable | B8: 320 | C8: 156 | D8: Working capital outflow
A9: Increase in Inventories | B9: 180 | C9: 78 | D9: Working capital outflow
A10: Increase in Accounts Payable | B10: 110 | C10: 72 | D10: Working capital inflow
A11: Increase in Deferred Revenue | B11: 200 | C11: 130 | D11: Working capital inflow
A12: Capital Expenditures | B12: 650 | C12: 390 | D12: Cash capex per cash flow stmt
A13: Acquisitions (cash paid) | B13: 400 | C13: 0 | D13: Inorganic M&A spend
A14: Total Debt | B14: 2000 | C14: 1200 | D14: Balance sheet — total borrowings
A15: Cash & Equivalents | B15: 900 | C15: 600 | D15: Balance sheet — liquid assets
... A19: Share Price | B19: 52 | C19: 38 | D19: Market price per share ($)
A21: 🔵 Blue = Hardcoded input | ⚫ Black = Formula | 🟢 Green = Cross-sheet link | 🟡 Yellow = Key assumption

Sheet Computed Metrics
A1: VelocityTech Inc. — Computed Financial Metrics | Q8.1 & Q8.2
A2: All formulas reference 'Input Data' sheet — change any input to auto-recalculate
A3: Line Item / Metric | B3: FY 2025 ($M) | C3: FY 2024 ($M) | D3: YoY Change
A5: Q8.1(a) Cash Flow from Operations — Indirect Method
A6: Formula: CFO = NI + D&A + SBC − ΔA/R − ΔInv + ΔA/P + ΔDeferred Rev
A7: Line Item | B7: FY 2025 | C7: FY 2024 | D7: YoY Δ
A8: Net Income | B8: ='Input Data'!B5 -> 780 | C8: ='Input Data'!C5 -> 507 | D8: =IF(C8<>0,(B8-C8)/ABS(C8),"N/A") -> 0.53846154
A9: Add: Depreciation & Amortisation | B9: ='Input Data'!B6 -> 260 | C9: ='Input Data'!C6 -> 195 | D9: =IF(C9<>0,(B9-C9)/ABS(C9),"N/A") -> 0.33333333
A10: Add: Stock-Based Compensation | B10: ='Input Data'!B7 -> 390 | C10: ='Input Data'!C7 -> 234 | D10: =IF(C10<>0,(B10-C10)/ABS(C10),"N/A") -> 0.66666667
A11: Less: Increase in Accounts Rec. | B11: =-'Input Data'!B8 -> -320 | C11: =-'Input Data'!C8 -> -156 | D11: =IF(C11<>0,(B11-C11)/ABS(C11),"N/A") -> -1.0512821
A12: Less: Increase in Inventories | B12: =-'Input Data'!B9 -> -180 | C12: =-'Input Data'!C9 -> -78 | D12: =IF(C12<>0,(B12-C12)/ABS(C12),"N/A") -> -1.3076923
A13: Add: Increase in Accounts Payable | B13: ='Input Data'!B10 -> 110 | C13: ='Input Data'!C10 -> 72 | D13: =IF(C13<>0,(B13-C13)/ABS(C13),"N/A") -> 0.52777778
A14: Add: Increase in Deferred Revenue | B14: ='Input Data'!B11 -> 200 | C14: ='Input Data'!C11 -> 130 | D14: =IF(C14<>0,(B14-C14)/ABS(C14),"N/A") -> 0.53846154
A15: Cash Flow from Operations (CFO) | B15: =SUM(B8:B14) -> 1240 | C15: =SUM(C8:C14) -> 904 | D15: =IF(C15<>0,(B15-C15)/ABS(C15),"N/A") -> 0.37168142
A16: Less: SBC (treated as economic cost) | B16: =-'Input Data'!B7 -> -390 | C16: =-'Input Data'!C7 -> -234 | D16: =IF(C16<>0,(B16-C16)/ABS(C16),"N/A") -> -0.66666667
A17: SBC-Adjusted CFO | B17: =B15+B16 -> 850 | C17: =C15+C16 -> 670 | D17: =IF(C17<>0,(B17-C17)/ABS(C17),"N/A") -> 0.26865672
A19: Q8.1(b) Free Cash Flow to Firm (FCFF = CFO − CapEx)
A20: Line Item | B20: FY 2025 | C20: FY 2024 | D20: YoY Δ
A21: Cash Flow from Operations (CFO) | B21: =B15 -> 1240 | C21: =C15 -> 904 | D21: =IF(C21<>0,(B21-C21)/ABS(C21),"N/A") -> 0.37168142
A22: Less: Capital Expenditures | B22: =-'Input Data'!B12 -> -650 | C22: =-'Input Data'!C12 -> -390 | D22: =IF(C22<>0,(B22-C22)/ABS(C22),"N/A") -> -0.66666667
A23: FCFF | B23: =B21+B22 -> 590 | C23: =C21+C22 -> 514 | D23: =IF(C23<>0,(B23-C23)/ABS(C23),"N/A") -> 0.14785992
A24: Less: Acquisitions (cash paid) | B24: =-'Input Data'!B13 -> -400 | C24: =-'Input Data'!C13 -> 0 | D24: =IF(C24<>0,(B24-C24)/ABS(C24),"N/A") -> N/A
A25: FCFF incl. Acquisitions | B25: =B23+B24 -> 190 | C25: =C23+C24 -> 514 | D25: =IF(C25<>0,(B25-C25)/ABS(C25),"N/A") -> -0.63035019
A26: CapEx as % of CFO | B26: ='Input Data'!B12/B15 -> 0.52419355 | C26: ='Input Data'!C12/C15 -> 0.43141593 | D26: =IF(C26<>0,(B26-C26)/ABS(C26),"N/A") -> 0.21505376
A28: Q8.1(c) Free Cash Flow to Equity (FCFE = FCFF + Net Borrowing)
A29: Line Item | B29: FY 2025 | C29: FY 2024 (N/A — no prior debt) | D29: YoY Δ
A30: FCFF | B30: =B23 -> 590
A31: Net Borrowing (ΔTotal Debt) | B31: ='Input Data'!B14-'Input Data'!C14 -> 800
A32: FCFE (FY 2025) | B32: =B30+B31 -> 1390
A34: Q8.1(d) Adjusted Net Income (NI − SBC)
A35: Line Item | B35: FY 2025 | C35: FY 2024 | D35: YoY Δ
A36: Reported Net Income | B36: ='Input Data'!B5 -> 780 | C36: ='Input Data'!C5 -> 507 | D36: =IF(C36<>0,(B36-C36)/ABS(C36),"N/A") -> 0.53846154
A37: Less: Stock-Based Compensation | B37: =-'Input Data'!B7 -> -390 | C37: =-'Input Data'!C7 -> -234 | D37: =IF(C37<>0,(B37-C37)/ABS(C37),"N/A") -> -0.66666667
A38: Adjusted Net Income | B38: =B36+B37 -> 390 | C38: =C36+C37 -> 273 | D38: =IF(C38<>0,(B38-C38)/ABS(C38),"N/A") -> 0.42857143
A39: SBC as % of Reported NI | B39: ='Input Data'!B7/'Input Data'!B5 -> 0.5 | C39: ='Input Data'!C7/'Input Data'!C5 -> 0.46153846 | D39: =IF(C39<>0,(B39-C39)/ABS(C39),"N/A") -> 0.083333333
A40: Reduction in 'real' earnings | B40: =1-B38/'Input Data'!B5 -> 0.5 | C40: =1-C38/'Input Data'!C5 -> 0.46153846 | D40: =IF(C40<>0,(B40-C40)/ABS(C40),"N/A") -> 0.083333333
A42: Q8.1(e) Accrual Ratio = (NI − CFO) / Total Assets
A43: Item | B43: FY 2025 | C43: FY 2024 | D43: YoY Δ
A44: Net Income ($M) | B44: ='Input Data'!B5 -> 780 | C44: ='Input Data'!C5 -> 507 | D44: =IF(C44<>0,(B44-C44)/ABS(C44),"N/A") -> 0.53846154
A45: CFO ($M) | B45: =B15 -> 1240 | C45: =C15 -> 904 | D45: =IF(C45<>0,(B45-C45)/ABS(C45),"N/A") -> 0.37168142
...

Sheet Valuation
A1: VelocityTech Inc. — Valuation & Short-Seller Analysis (Q8.2)
A2: ▼ KEY ASSUMPTIONS — change these to recalculate implied values
A3: Justified EV/FCFF Multiple (×) | B3: 25 | C3: Change me — sustainable growth multiple
A4: Estimated Acquired Revenue (%) | B4: 0.1 | C4: % of FY2025 rev from acquisitions
A6: SECTION 1 — Enterprise Value Calculation
A7: Shares Outstanding (M) | B7: ='Input Data'!B18 -> 600 | C7: From input data
A8: Share Price ($) | B8: ='Input Data'!B19 -> 52 | C8: From input data
A9: Market Capitalisation ($M) | B9: ='Input Data'!B18*'Input Data'!B19 -> 31200 | C9: Shares × Price
A10: + Total Debt ($M) | B10: ='Input Data'!B14 -> 2000 | C10: From input data
A11: − Cash & Equivalents ($M) | B11: ='Input Data'!B15 -> 900 | C11: From input data
A12: Enterprise Value (EV) () | B12: =B9+B10-B11 -> 32300
A13: FCFF ($M) [from Computed Metrics] | B13: ='Computed Metrics'!B23 -> 590 | C13: Prior year N/A
A14: EV / FCFF Multiple (Actual) | B14: =B12/B13 -> 54.745763 | C14: Market-implied multiple
A16: SECTION 2 — P/E Analysis (Reported vs SBC-Adjusted)
A17: Metric | B17: Reported | C17: SBC-Adjusted
A18: Net Income ($M) | B18: ='Input Data'!B5 -> 780 | C18: ='Computed Metrics'!B38 -> 390
A19: Shares Outstanding (M) | B19: ='Input Data'!B18 -> 600 | C19: ='Input Data'!B18 -> 600
A20: EPS ($) | B20: =B18/'Input Data'!B18 -> 1.3 | C20: =C18/'Input Data'!B18 -> 0.65
A21: Share Price ($) | B21: ='Input Data'!B19 -> 52 | C21: ='Input Data'!B19 -> 52
A22: P/E Ratio | B22: ='Input Data'!B19/B20 -> 40 | C22: ='Input Data'!B19/C20 -> 80
A24: SECTION 3 — Organic vs Reported Revenue Growth
A25: Item | B25: Value | C25: Notes
A26: Reported FY2025 Revenue ($M) | B26: ='Input Data'!B4 -> 5200 | C26: From input data
A27: Less: Acquired Revenue ($M) | B27: =-'Input Data'!B4*B4 -> -520 | C27: Prior year N/A
A28: Organic FY2025 Revenue () | B28: ='Input Data'!B4+B27 -> 4680
A29: FY2024 Revenue (base) ($M) | B29: ='Input Data'!C4 -> 3900
A30: Organic Revenue Growth Rate | B30: =(B28-'Input Data'!C4)/'Input Data'!C4 -> 0.2 | C30: Organic-only growth
A31: Reported Revenue Growth Rate | B31: =('Input Data'!B4-'Input Data'!C4)/'Input Data'!C4 -> 0.33333333 | C31: Headline reported growth
A33: SECTION 4 — Implied Fair Value per Share
A34: Step | B34: Calculation / Value | C34: Notes
A35: FCFF ($M) | B35: ='Computed Metrics'!B23 -> 590 | C35: From Computed Metrics sheet
A36: Justified EV/FCFF Multiple (×) | B36: =B3 -> 25 | C36: Assumption — see B3
A37: Implied Enterprise Value () | B37: =B35*B36 -> 14750
A38: Less: Net Debt (Debt − Cash) ($M) | B38: =-('Input Data'!B14-'Input Data'!B15) -> -1100
A39: Implied Equity Value () | B39: =B37+B38 -> 13650
A40: ÷ Shares Outstanding (M) | B40: ='Input Data'!B18 -> 600
A41: Implied Fair Value per Share ($) | B41: =B39/B40 -> 22.75
A42: Current Market Price ($) | B42: ='Input Data'!B19 -> 52
A43: Implied Premium / (Discount) vs Market | B43: =('Input Data'!B19-B41)/B41 -> 1.2857143 | C43: Positive = overvalued; Negative = undervalued

Sheet Red Flag Analysis
A1: VelocityTech Inc. — Red Flag Summary (Q8.1 Forensic Analysis)
A2: Flag | B2: Description | C2: Computed Metric | D2: Detail
A3: 🔴 RF1 | B3: SBC = 50% of Net Income | C3: ='Computed Metrics'!B38/'Input Data'!B5 -> 0.5 | D3: SBC of $390M equals exactly 50% of reported NI. Adjusted NI is $390M — half the headline. Dilutes shareholders.
A4: 🔴 RF2 | B4: A/R growing 2× faster than revenue | C4: =IFERROR(('Input Data'!B5-'Input Data'!C5)/ABS('Input Data'!C5)-('Input Data'!B1-'Input Data'!C1)/ABS('Input Data'!C1),"N/A") -> N/A | D4: AR increment grew 105% vs 33.3% revenue growth. Signals aggressive rev recognition or credit deterioration.
A5: 🔴 RF3 | B5: EV/FCFF of 54.7× vs 25× justified | C5: =Valuation!B14 -> 54.745763 | D5: At 54.7× FCFF, market extrapolates unsustainable inorganic growth. Implies 56% overvaluation at 25× justified.
A7: OVERALL ASSESSMENT SCORECARD (auto-linked to computed sheets)
A8: Metric | B8: FY 2025 | C8: FY 2024 | D8: Signal
A9: CFO ($M) | B9: ='Computed Metrics'!B15 -> 1240 | C9: ='Computed Metrics'!C15 -> 904 | D9: Neutral (SBC-inflated)
A10: FCFF ($M) | B10: ='Computed Metrics'!B23 -> 590 | C10: ='Computed Metrics'!C23 -> 514 | D10: Modest growth
A11: Adjusted Net Income | B11: ='Computed Metrics'!B38 -> 390 | C11: ='Computed Metrics'!C38 -> 273 | D11: 🔴 50% haircut from NI
A12: Accrual Ratio | B12: ='Computed Metrics'!B48 -> -0.058974359 | C12: ='Computed Metrics'!C48 -> -0.073518519 | D12: Neutral (SBC-distorted)
A13: Cash-to-Earnings | B13: ='Computed Metrics'!B54 -> 1.5897436 | C13: ='Computed Metrics'!C54 -> 1.7830375 | D13: Deteriorating
A14: Reported P/E | B14: =Valuation!B22 -> 40 | C14: ~41× | D14: 🔴 Rich
A15: SBC-Adjusted P/E | B15: =Valuation!C22 -> 80 | C15: N/A | D15: 🔴 Extreme
A16: EV/FCFF | B16: =Valuation!B14 -> 54.745763 | C16: N/A | D16: 🔴 Severely overvalued
A17: Implied Fair Value/sh | B17: =Valuation!B41 -> 22.75 | C17: N/A | D17: 56% below market price

Sheet Template (Upload)
A1: UPLOAD TEMPLATE — Replace placeholder values in blue, keep row labels EXACTLY as shown
A2: ⬇ This sheet is the upload template for the Streamlit dashboard — download, fill in, upload
A3: Item | B3: FY 2025 | C3: FY 2024
A4: Revenue
A5: Net Income
A6: Depreciation & Amortisation
A7: Stock-Based Compensation (non-cash)
A8: Increase in Accounts Receivable
A9: Increase in Inventories
A10: Increase in Accounts Payable
A11: Increase in Deferred Revenue
A12: Capital Expenditures
A13: Acquisitions (cash paid)
A14: Total Debt
A15: Cash & Equivalents
... A20: ℹ️ Enter raw numbers only (no $ signs or commas). Share Price can be numeric or include $.
